Workbook

Sheet Painel
B1: ="Transformação corporal · 04/01/2026 a "&RIGHT("0"&DAY(MAX('Medições Corporais'!$A$4:$A$147)),2)&"/"&RIGHT("0"&MONTH(MAX('Medições Corporais'!$A$4:$A$147)),2)&"/"&YEAR(MAX('Medições Corporais'!$A$4:$A$147))
B2: ="Última leitura: "&RIGHT("0"&DAY(INDEX('Medições Corporais'!$A$4:$A$147,MATCH(MAX('Medições Corporais'!$R$4:$R$147),'Medições Corporais'!$R$4:$R$147,0))),2)&"/"&RIGHT("0"&MONTH(INDEX('Medições Corporais'!$A$4:$A$147,MATCH(MAX('Medições Corporais'!$R$4:$R$147),'Medições Corporais'!$R$4:$R$147,0))),2)&"/"&YEAR(INDEX('Medições Corporais'!$A$4:$A$147,MATCH(MAX('Medições Corporais'!$R$4:$R$147),'Medições Corporais'!$R$4:$R$147,0)))&" às "&RIGHT("0"&HOUR(INDEX('Medições Corporais'!$A$4:$A$147,MATCH(MAX('Medições Corporais'!$R$4:$R$147),'Medições Corporais'!$R$4:$R$147,0))),2)&":"&RIGHT("0"&MINUTE(INDEX('Medições Corporais'!$A$4:$A$147,MATCH(MAX('Medições Corporais'!$R$4:$R$147),'Medições Corporais'!$R$4:$R$147,0))),2)&" · "&COUNT('Medições Corporais'!$A$4:$A$147)&" leituras aceites · Atualizado em 11/10/2026 16:40"
B4: Último peso | F4: Peso (média 7 dias) | J4: Peso desde o início | N4: Ritmo recente
B5: =INDEX('Medições Corporais'!$B$4:$B$147,MATCH(MAX('Medições Corporais'!$R$4:$R$147),'Medições Corporais'!$R$4:$R$147,0)) | F5: =AVERAGEIFS('Medições Corporais'!$B$4:$B$147,'Medições Corporais'!$A$4:$A$147,">"&MAX('Medições Corporais'!$A$4:$A$147)-7) | J5: =AVERAGEIFS('Medições Corporais'!$B$4:$B$147,'Medições Corporais'!$A$4:$A$147,">"&MAX('Medições Corporais'!$A$4:$A$147)-7)-AVERAGEIFS('Medições Corporais'!$B$4:$B$147,'Medições Corporais'!$A$4:$A$147,"<"&MIN('Medições Corporais'!$A$4:$A$147)+7) | N5: =IFERROR((AVERAGEIFS('Medições Corporais'!$B$4:$B$147,'Medições Corporais'!$A$4:$A$147,">"&MAX('Medições Corporais'!$A$4:$A$147)-7)-AVERAGEIFS('Medições Corporais'!$B$4:$B$147,'Medições Corporais'!$A$4:$A$147,">"&MAX('Medições Corporais'!$A$4:$A$147)-28,'Medições Corporais'!$A$4:$A$147,"<="&MAX('Medições Corporais'!$A$4:$A$147)-21))/3,"")
B8: ="leitura mais recente" | F8: ="últimos 7 dias" | J8: ="média 7 dias: atual − inicial" | N8: ="últimas 4 semanas"
B10: Gordura (média 7 dias) | F10: Gordura desde o início | J10: Músculo (média 7 dias) | N10: Músculo desde o início
B11: =AVERAGEIFS('Medições Corporais'!$D$4:$D$147,'Medições Corporais'!$A$4:$A$147,">"&MAX('Medições Corporais'!$A$4:$A$147)-7) | F11: =AVERAGEIFS('Medições Corporais'!$D$4:$D$147,'Medições Corporais'!$A$4:$A$147,">"&MAX('Medições Corporais'!$A$4:$A$147)-7)-AVERAGEIFS('Medições Corporais'!$D$4:$D$147,'Medições Corporais'!$A$4:$A$147,"<"&MIN('Medições Corporais'!$A$4:$A$147)+7) | J11: =AVERAGEIFS('Medições Corporais'!$G$4:$G$147,'Medições Corporais'!$A$4:$A$147,">"&MAX('Medições Corporais'!$A$4:$A$147)-7) | N11: =AVERAGEIFS('Medições Corporais'!$G$4:$G$147,'Medições Corporais'!$A$4:$A$147,">"&MAX('Medições Corporais'!$A$4:$A$147)-7)-AVERAGEIFS('Medições Corporais'!$G$4:$G$147,'Medições Corporais'!$A$4:$A$147,"<"&MIN('Medições Corporais'!$A$4:$A$147)+7)
B14: ="estimativa da balança" | F14: ="pontos percentuais" | J14: ="estimativa da balança" | N14: ="média 7 dias: atual − inicial"
B16: Última cintura | F16: Cintura desde o início | J16: Último pescoço | N16: Pescoço desde o início
B17: =IF(COUNT('Medidas Manuais'!$C$4:$C$25)=0,"",SUMIFS('Medidas Manuais'!$C$4:$C$25,'Medidas Manuais'!$B$4:$B$25,_xlfn.MAXIFS('Medidas Manuais'!$B$4:$B$25,'Medidas Manuais'!$C$4:$C$25,">0"))) | F17: =IF(COUNT('Medidas Manuais'!$C$4:$C$25)<2,"",SUMIFS('Medidas Manuais'!$C$4:$C$25,'Medidas Manuais'!$B$4:$B$25,_xlfn.MAXIFS('Medidas Manuais'!$B$4:$B$25,'Medidas Manuais'!$C$4:$C$25,">0"))-SUMIFS('Medidas Manuais'!$C$4:$C$25,'Medidas Manuais'!$B$4:$B$25,_xlfn.MINIFS('Medidas Manuais'!$B$4:$B$25,'Medidas Manuais'!$C$4:$C$25,">0"))) | J17: =IF(COUNT('Medidas Manuais'!$E$4:$E$25)=0,"",SUMIFS('Medidas Manuais'!$E$4:$E$25,'Medidas Manuais'!$B$4:$B$25,_xlfn.MAXIFS('Medidas Manuais'!$B$4:$B$25,'Medidas Manuais'!$E$4:$E$25,">0"))) | N17: =IF(COUNT('Medidas Manuais'!$E$4:$E$25)<2,"",SUMIFS('Medidas Manuais'!$E$4:$E$25,'Medidas Manuais'!$B$4:$B$25,_xlfn.MAXIFS('Medidas Manuais'!$B$4:$B$25,'Medidas Manuais'!$E$4:$E$25,">0"))-SUMIFS('Medidas Manuais'!$E$4:$E$25,'Medidas Manuais'!$B$4:$B$25,_xlfn.MINIFS('Medidas Manuais'!$B$4:$B$25,'Medidas Manuais'!$E$4:$E$25,">0")))
B20: =IF(COUNT('Medidas Manuais'!$C$4:$C$25)=0,"","medida em "&RIGHT("0"&DAY(_xlfn.MAXIFS('Medidas Manuais'!$B$4:$B$25,'Medidas Manuais'!$C$4:$C$25,">0")),2)&"/"&RIGHT("0"&MONTH(_xlfn.MAXIFS('Medidas Manuais'!$B$4:$B$25,'Medidas Manuais'!$C$4:$C$25,">0")),2)&"/"&YEAR(_xlfn.MAXIFS('Medidas Manuais'!$B$4:$B$25,'Medidas Manuais'!$C$4:$C$25,">0"))) | F20: ="última − primeira medição" | J20: =IF(COUNT('Medidas Manuais'!$E$4:$E$25)=0,"","medido em "&RIGHT("0"&DAY(_xlfn.MAXIFS('Medidas Manuais'!$B$4:$B$25,'Medidas Manuais'!$E$4:$E$25,">0")),2)&"/"&RIGHT("0"&MONTH(_xlfn.MAXIFS('Medidas Manuais'!$B$4:$B$25,'Medidas Manuais'!$E$4:$E$25,">0")),2)&"/"&YEAR(_xlfn.MAXIFS('Medidas Manuais'!$B$4:$B$25,'Medidas Manuais'!$E$4:$E$25,">0"))) | N20: ="última − primeira medição"
B98: Gráficos de peso, gordura e músculo: pontos = leituras; linha = média móvel de 7 dias. Cintura e pescoço: pontos = medições reais; tracejado = semanas sem medição (só visual, sem valores inventados). As escalas e os tracejados são recalculados em cada atualização.

Sheet Resumo Mensal
B1: Resumo mensal
B2: Atualizado em 11/10/2026 16:40
A3: Mês | B3: Início | C3: Fim | D3: Leituras | E3: Dias com medição | F3: Período parcial | G3: Peso médio (kg) | H3: Variação do peso (kg) | I3: Gordura média (%) | J3: Variação da gordura (pp) | K3: Músculo médio (kg) | L3: Massa gorda média (kg) | M3: Água média (%) | N3: Proteína média (%) | O3: Massa óssea média (kg) | P3: IMC médio | Q3: Gordura visceral média (índice) | R3: Idade corporal média (anos) | S3: Pontuação corporal média | T3: Cintura média (cm) | U3: Pescoço médio (cm)
A4: 46023 | B4: 46023 | C4: 46053 | D4: =COUNTIFS('Medições Corporais'!$A$4:$A$147,">="&$B4,'Medições Corporais'!$A$4:$A$147,"<"&$C4+1) | E4: =SUMPRODUCT(('Medições Corporais'!$Q$4:$Q$147>=$B4)*('Medições Corporais'!$Q$4:$Q$147<=$C4)/COUNTIF('Medições Corporais'!$Q$4:$Q$147,'Medições Corporais'!$Q$4:$Q$147)) | F4: =IF($D4=0,"",IF(OR($B4<DATE(2026,1,4),$C4>MAX('Medições Corporais'!$Q$4:$Q$147)),"Sim","Não")) | G4: =IF($D4=0,"",AVERAGEIFS('Medições Corporais'!$B$4:$B$147,'Medições Corporais'!$A$4:$A$147,">="&$B4,'Medições Corporais'!$A$4:$A$147,"<"&$C4+1)) | H4: ="" | I4: =IF($D4=0,"",AVERAGEIFS('Medições Corporais'!$D$4:$D$147,'Medições Corporais'!$A$4:$A$147,">="&$B4,'Medições Corporais'!$A$4:$A$147,"<"&$C4+1)) | J4: ="" | K4: =IF($D4=0,"",AVERAGEIFS('Medições Corporais'!$G$4:$G$147,'Medições Corporais'!$A$4:$A$147,">="&$B4,'Medições Corporais'!$A$4:$A$147,"<"&$C4+1)) | L4: =IF($D4=0,"",AVERAGEIFS('Medições Corporais'!$I$4:$I$147,'Medições Corporais'!$A$4:$A$147,">="&$B4,'Medições Corporais'!$A$4:$A$147,"<"&$C4+1)) | M4: =IF($D4=0,"",AVERAGEIFS('Medições Corporais'!$E$4:$E$147,'Medições Corporais'!$A$4:$A$147,">="&$B4,'Medições Corporais'!$A$4:$A$147,"<"&$C4+1)) | N4: =IF($D4=0,"",AVERAGEIFS('Medições Corporais'!$H$4:$H$147,'Medições Corporais'!$A$4:$A$147,">="&$B4,'Medições Corporais'!$A$4:$A$147,"<"&$C4+1)) | O4: =IF($D4=0,"",AVERAGEIFS('Medições Corporais'!$F$4:$F$147,'Medições Corporais'!$A$4:$A$147,">="&$B4,'Medições Corporais'!$A$4:$A$147,"<"&$C4+1)) | P4: =IF($D4=0,"",AVERAGEIFS('Medições Corporais'!$C$4:$C$147,'Medições Corporais'!$A$4:$A$147,">="&$B4,'Medições Corporais'!$A$4:$A$147,"<"&$C4+1)) | Q4: =IF($D4=0,"",AVERAGEIFS('Medições Corporais'!$J$4:$J$147,'Medições Corporais'!$A$4:$A$147,">="&$B4,'Medições Corporais'!$A$4:$A$147,"<"&$C4+1)) | R4: =IF($D4=0,"",AVERAGEIFS('Medições Corporais'!$L$4:$L$147,'Medições Corporais'!$A$4:$A$147,">="&$B4,'Medições Corporais'!$A$4:$A$147,"<"&$C4+1)) | S4: =IF($D4=0,"",AVERAGEIFS('Medições Corporais'!$M$4:$M$147,'Medições Corporais'!$A$4:$A$147,">="&$B4,'Medições Corporais'!$A$4:$A$147,"<"&$C4+1)) | T4: =IFERROR(AVERAGEIFS('Medidas Manuais'!$C$4:$C$25,'Medidas Manuais'!$B$4:$B$25,">="&$B4,'Medidas Manuais'!$B$4:$B$25,"<"&$C4+1),"") | U4: =IFERROR(AVERAGEIFS('Medidas Manuais'!$E$4:$E$25,'Medidas Manuais'!$B$4:$B$25,">="&$B4,'Medidas Manuais'!$B$4:$B$25,"<"&$C4+1),"")
A5: 46054 | B5: 46054 | C5: 46081 | D5: =COUNTIFS('Medições Corporais'!$A$4:$A$147,">="&$B5,'Medições Corporais'!$A$4:$A$147,"<"&$C5+1) | E5: =SUMPRODUCT(('Medições Corporais'!$Q$4:$Q$147>=$B5)*('Medições Corporais'!$Q$4:$Q$147<=$C5)/COUNTIF('Medições Corporais'!$Q$4:$Q$147,'Medições Corporais'!$Q$4:$Q$147)) | F5: =IF($D5=0,"",IF(OR($B5<DATE(2026,1,4),$C5>MAX('Medições Corporais'!$Q$4:$Q$147)),"Sim","Não")) | G5: =IF($D5=0,"",AVERAGEIFS('Medições Corporais'!$B$4:$B$147,'Medições Corporais'!$A$4:$A$147,">="&$B5,'Medições Corporais'!$A$4:$A$147,"<"&$C5+1)) | H5: =IF(OR(G5="",G4=""),"",G5-G4) | I5: =IF($D5=0,"",AVERAGEIFS('Medições Corporais'!$D$4:$D$147,'Medições Corporais'!$A$4:$A$147,">="&$B5,'Medições Corporais'!$A$4:$A$147,"<"&$C5+1)) | J5: =IF(OR(I5="",I4=""),"",I5-I4) | K5: =IF($D5=0,"",AVERAGEIFS('Medições Corporais'!$G$4:$G$147,'Medições Corporais'!$A$4:$A$147,">="&$B5,'Medições Corporais'!$A$4:$A$147,"<"&$C5+1)) | L5: =IF($D5=0,"",AVERAGEIFS('Medições Corporais'!$I$4:$I$147,'Medições Corporais'!$A$4:$A$147,">="&$B5,'Medições Corporais'!$A$4:$A$147,"<"&$C5+1)) | M5: =IF($D5=0,"",AVERAGEIFS('Medições Corporais'!$E$4:$E$147,'Medições Corporais'!$A$4:$A$147,">="&$B5,'Medições Corporais'!$A$4:$A$147,"<"&$C5+1)) | N5: =IF($D5=0,"",AVERAGEIFS('Medições Corporais'!$H$4:$H$147,'Medições Corporais'!$A$4:$A$147,">="&$B5,'Medições Corporais'!$A$4:$A$147,"<"&$C5+1)) | O5: =IF($D5=0,"",AVERAGEIFS('Medições Corporais'!$F$4:$F$147,'Medições Corporais'!$A$4:$A$147,">="&$B5,'Medições Corporais'!$A$4:$A$147,"<"&$C5+1)) | P5: =IF($D5=0,"",AVERAGEIFS('Medições Corporais'!$C$4:$C$147,'Medições Corporais'!$A$4:$A$147,">="&$B5,'Medições Corporais'!$A$4:$A$147,"<"&$C5+1)) | Q5: =IF($D5=0,"",AVERAGEIFS('Medições Corporais'!$J$4:$J$147,'Medições Corporais'!$A$4:$A$147,">="&$B5,'Medições Corporais'!$A$4:$A$147,"<"&$C5+1)) | R5: =IF($D5=0,"",AVERAGEIFS('Medições Corporais'!$L$4:$L$147,'Medições Corporais'!$A$4:$A$147,">="&$B5,'Medições Corporais'!$A$4:$A$147,"<"&$C5+1)) | S5: =IF($D5=0,"",AVERAGEIFS('Medições Corporais'!$M$4:$M$147,'Medições Corporais'!$A$4:$A$147,">="&$B5,'Medições Corporais'!$A$4:$A$147,"<"&$C5+1)) | T5: =IFERROR(AVERAGEIFS('Medidas Manuais'!$C$4:$C$25,'Medidas Manuais'!$B$4:$B$25,">="&$B5,'Medidas Manuais'!$B$4:$B$25,"<"&$C5+1),"") | U5: =IFERROR(AVERAGEIFS('Medidas Manuais'!$E$4:$E$25,'Medidas Manuais'!$B$4:$B$25,">="&$B5,'Medidas Manuais'!$B$4:$B$25,"<"&$C5+1),"")
A6: 46082 | B6: 46082 | C6: 46112 | D6: =COUNTIFS('Medições Corporais'!$A$4:$A$147,">="&$B6,'Medições Corporais'!$A$4:$A$147,"<"&$C6+1) | E6: =SUMPRODUCT(('Medições Corporais'!$Q$4:$Q$147>=$B6)*('Medições Corporais'!$Q$4:$Q$147<=$C6)/COUNTIF('Medições Corporais'!$Q$4:$Q$147,'Medições Corporais'!$Q$4:$Q$147)) | F6: =IF($D6=0,"",IF(OR($B6<DATE(2026,1,4),$C6>MAX('Medições Corporais'!$Q$4:$Q$147)),"Sim","Não")) | G6: =IF($D6=0,"",AVERAGEIFS('Medições Corporais'!$B$4:$B$147,'Medições Corporais'!$A$4:$A$147,">="&$B6,'Medições Corporais'!$A$4:$A$147,"<"&$C6+1)) | H6: =IF(OR(G6="",G5=""),"",G6-G5) | I6: =IF($D6=0,"",AVERAGEIFS('Medições Corporais'!$D$4:$D$147,'Medições Corporais'!$A$4:$A$147,">="&$B6,'Medições Corporais'!$A$4:$A$147,"<"&$C6+1)) | J6: =IF(OR(I6="",I5=""),"",I6-I5) | K6: =IF($D6=0,"",AVERAGEIFS('Medições Corporais'!$G$4:$G$147,'Medições Corporais'!$A$4:$A$147,">="&$B6,'Medições Corporais'!$A$4:$A$147,"<"&$C6+1)) | L6: =IF($D6=0,"",AVERAGEIFS('Medições Corporais'!$I$4:$I$147,'Medições Corporais'!$A$4:$A$147,">="&$B6,'Medições Corporais'!$A$4:$A$147,"<"&$C6+1)) | M6: =IF($D6=0,"",AVERAGEIFS('Medições Corporais'!$E$4:$E$147,'Medições Corporais'!$A$4:$A$147,">="&$B6,'Medições Corporais'!$A$4:$A$147,"<"&$C6+1)) | N6: =IF($D6=0,"",AVERAGEIFS('Medições Corporais'!$H$4:$H$147,'Medições Corporais'!$A$4:$A$147,">="&$B6,'Medições Corporais'!$A$4:$A$147,"<"&$C6+1)) | O6: =IF($D6=0,"",AVERAGEIFS('Medições Corporais'!$F$4:$F$147,'Medições Corporais'!$A$4:$A$147,">="&$B6,'Medições Corporais'!$A$4:$A$147,"<"&$C6+1)) | P6: =IF($D6=0,"",AVERAGEIFS('Medições Corporais'!$C$4:$C$147,'Medições Corporais'!$A$4:$A$147,">="&$B6,'Medições Corporais'!$A$4:$A$147,"<"&$C6+1)) | Q6: =IF($D6=0,"",AVERAGEIFS('Medições Corporais'!$J$4:$J$147,'Medições Corporais'!$A$4:$A$147,">="&$B6,'Medições Corporais'!$A$4:$A$147,"<"&$C6+1)) | R6: =IF($D6=0,"",AVERAGEIFS('Medições Corporais'!$L$4:$L$147,'Medições Corporais'!$A$4:$A$147,">="&$B6,'Medições Corporais'!$A$4:$A$147,"<"&$C6+1)) | S6: =IF($D6=0,"",AVERAGEIFS('Medições Corporais'!$M$4:$M$147,'Medições Corporais'!$A$4:$A$147,">="&$B6,'Medições Corporais'!$A$4:$A$147,"<"&$C6+1)) | T6: =IFERROR(AVERAGEIFS('Medidas Manuais'!$C$4:$C$25,'Medidas Manuais'!$B$4:$B$25,">="&$B6,'Medidas Manuais'!$B$4:$B$25,"<"&$C6+1),"") | U6: =IFERROR(AVERAGEIFS('Medidas Manuais'!$E$4:$E$25,'Medidas Manuais'!$B$4:$B$25,">="&$B6,'Medidas Manuais'!$B$4:$B$25,"<"&$C6+1),"")
A7: 46113 | B7: 46113 | C7: 46142 | D7: =COUNTIFS('Medições Corporais'!$A$4:$A$147,">="&$B7,'Medições Corporais'!$A$4:$A$147,"<"&$C7+1) | E7: =SUMPRODUCT(('Medições Corporais'!$Q$4:$Q$147>=$B7)*('Medições Corporais'!$Q$4:$Q$147<=$C7)/COUNTIF('Medições Corporais'!$Q$4:$Q$147,'Medições Corporais'!$Q$4:$Q$147)) | F7: =IF($D7=0,"",IF(OR($B7<DATE(2026,1,4),$C7>MAX('Medições Corporais'!$Q$4:$Q$147)),"Sim","Não")) | G7: =IF($D7=0,"",AVERAGEIFS('Medições Corporais'!$B$4:$B$147,'Medições Corporais'!$A$4:$A$147,">="&$B7,'Medições Corporais'!$A$4:$A$147,"<"&$C7+1)) | H7: =IF(OR(G7="",G6=""),"",G7-G6) | I7: =IF($D7=0,"",AVERAGEIFS('Medições Corporais'!$D$4:$D$147,'Medições Corporais'!$A$4:$A$147,">="&$B7,'Medições Corporais'!$A$4:$A$147,"<"&$C7+1)) | J7: =IF(OR(I7="",I6=""),"",I7-I6) | K7: =IF($D7=0,"",AVERAGEIFS('Medições Corporais'!$G$4:$G$147,'Medições Corporais'!$A$4:$A$147,">="&$B7,'Medições Corporais'!$A$4:$A$147,"<"&$C7+1)) | L7: =IF($D7=0,"",AVERAGEIFS('Medições Corporais'!$I$4:$I$147,'Medições Corporais'!$A$4:$A$147,">="&$B7,'Medições Corporais'!$A$4:$A$147,"<"&$C7+1)) | M7: =IF($D7=0,"",AVERAGEIFS('Medições Corporais'!$E$4:$E$147,'Medições Corporais'!$A$4:$A$147,">="&$B7,'Medições Corporais'!$A$4:$A$147,"<"&$C7+1)) | N7: =IF($D7=0,"",AVERAGEIFS('Medições Corporais'!$H$4:$H$147,'Medições Corporais'!$A$4:$A$147,">="&$B7,'Medições Corporais'!$A$4:$A$147,"<"&$C7+1)) | O7: =IF($D7=0,"",AVERAGEIFS('Medições Corporais'!$F$4:$F$147,'Medições Corporais'!$A$4:$A$147,">="&$B7,'Medições Corporais'!$A$4:$A$147,"<"&$C7+1)) | P7: =IF($D7=0,"",AVERAGEIFS('Medições Corporais'!$C$4:$C$147,'Medições Corporais'!$A$4:$A$147,">="&$B7,'Medições Corporais'!$A$4:$A$147,"<"&$C7+1)) | Q7: =IF($D7=0,"",AVERAGEIFS('Medições Corporais'!$J$4:$J$147,'Medições Corporais'!$A$4:$A$147,">="&$B7,'Medições Corporais'!$A$4:$A$147,"<"&$C7+1)) | R7: =IF($D7=0,"",AVERAGEIFS('Medições Corporais'!$L$4:$L$147,'Medições Corporais'!$A$4:$A$147,">="&$B7,'Medições Corporais'!$A$4:$A$147,"<"&$C7+1)) | S7: =IF($D7=0,"",AVERAGEIFS('Medições Corporais'!$M$4:$M$147,'Medições Corporais'!$A$4:$A$147,">="&$B7,'Medições Corporais'!$A$4:$A$147,"<"&$C7+1)) | T7: =IFERROR(AVERAGEIFS('Medidas Manuais'!$C$4:$C$25,'Medidas Manuais'!$B$4:$B$25,">="&$B7,'Medidas Manuais'!$B$4:$B$25,"<"&$C7+1),"") | U7: =IFERROR(AVERAGEIFS('Medidas Manuais'!$E$4:$E$25,'Medidas Manuais'!$B$4:$B$25,">="&$B7,'Medidas Manuais'!$B$4:$B$25,"<"&$C7+1),"")
A8: 46143 | B8: 46143 | C8: 46173 | D8: =COUNTIFS('Medições Corporais'!$A$4:$A$147,">="&$B8,'Medições Corporais'!$A$4:$A$147,"<"&$C8+1) | E8: =SUMPRODUCT(('Medições Corporais'!$Q$4:$Q$147>=$B8)*('Medições Corporais'!$Q$4:$Q$147<=$C8)/COUNTIF('Medições Corporais'!$Q$4:$Q$147,'Medições Corporais'!$Q$4:$Q$147)) | F8: =IF($D8=0,"",IF(OR($B8<DATE(2026,1,4),$C8>MAX('Medições Corporais'!$Q$4:$Q$147)),"Sim","Não")) | G8: =IF($D8=0,"",AVERAGEIFS('Medições Corporais'!$B$4:$B$147,'Medições Corporais'!$A$4:$A$147,">="&$B8,'Medições Corporais'!$A$4:$A$147,"<"&$C8+1)) | H8: =IF(OR(G8="",G7=""),"",G8-G7) | I8: =IF($D8=0,"",AVERAGEIFS('Medições Corporais'!$D$4:$D$147,'Medições Corporais'!$A$4:$A$147,">="&$B8,'Medições Corporais'!$A$4:$A$147,"<"&$C8+1)) | J8: =IF(OR(I8="",I7=""),"",I8-I7) | K8: =IF($D8=0,"",AVERAGEIFS('Medições Corporais'!$G$4:$G$147,'Medições Corporais'!$A$4:$A$147,">="&$B8,'Medições Corporais'!$A$4:$A$147,"<"&$C8+1)) | L8: =IF($D8=0,"",AVERAGEIFS('Medições Corporais'!$I$4:$I$147,'Medições Corporais'!$A$4:$A$147,">="&$B8,'Medições Corporais'!$A$4:$A$147,"<"&$C8+1)) | M8: =IF($D8=0,"",AVERAGEIFS('Medições Corporais'!$E$4:$E$147,'Medições Corporais'!$A$4:$A$147,">="&$B8,'Medições Corporais'!$A$4:$A$147,"<"&$C8+1)) | N8: =IF($D8=0,"",AVERAGEIFS('Medições Corporais'!$H$4:$H$147,'Medições Corporais'!$A$4:$A$147,">="&$B8,'Medições Corporais'!$A$4:$A$147,"<"&$C8+1)) | O8: =IF($D8=0,"",AVERAGEIFS('Medições Corporais'!$F$4:$F$147,'Medições Corporais'!$A$4:$A$147,">="&$B8,'Medições Corporais'!$A$4:$A$147,"<"&$C8+1)) | P8: =IF($D8=0,"",AVERAGEIFS('Medições Corporais'!$C$4:$C$147,'Medições Corporais'!$A$4:$A$147,">="&$B8,'Medições Corporais'!$A$4:$A$147,"<"&$C8+1)) | Q8: =IF($D8=0,"",AVERAGEIFS('Medições Corporais'!$J$4:$J$147,'Medições Corporais'!$A$4:$A$147,">="&$B8,'Medições Corporais'!$A$4:$A$147,"<"&$C8+1)) | R8: =IF($D8=0,"",AVERAGEIFS('Medições Corporais'!$L$4:$L$147,'Medições Corporais'!$A$4:$A$147,">="&$B8,'Medições Corporais'!$A$4:$A$147,"<"&$C8+1)) | S8: =IF($D8=0,"",AVERAGEIFS('Medições Corporais'!$M$4:$M$147,'Medições Corporais'!$A$4:$A$147,">="&$B8,'Medições Corporais'!$A$4:$A$147,"<"&$C8+1)) | T8: =IFERROR(AVERAGEIFS('Medidas Manuais'!$C$4:$C$25,'Medidas Manuais'!$B$4:$B$25,">="&$B8,'Medidas Manuais'!$B$4:$B$25,"<"&$C8+1),"") | U8: =IFERROR(AVERAGEIFS('Medidas Manuais'!$E$4:$E$25,'Medidas Manuais'!$B$4:$B$25,">="&$B8,'Medidas Manuais'!$B$4:$B$25,"<"&$C8+1),"")
A9: 46174 | B9: 46174 | C9: 46203 | D9: =COUNTIFS('Medições Corporais'!$A$4:$A$147,">="&$B9,'Medições Corporais'!$A$4:$A$147,"<"&$C9+1) | E9: =SUMPRODUCT(('Medições Corporais'!$Q$4:$Q$147>=$B9)*('Medições Corporais'!$Q$4:$Q$147<=$C9)/COUNTIF('Medições Corporais'!$Q$4:$Q$147,'Medições Corporais'!$Q$4:$Q$147)) | F9: =IF($D9=0,"",IF(OR($B9<DATE(2026,1,4),$C9>MAX('Medições Corporais'!$Q$4:$Q$147)),"Sim","Não")) | G9: =IF($D9=0,"",AVERAGEIFS('Medições Corporais'!$B$4:$B$147,'Medições Corporais'!$A$4:$A$147,">="&$B9,'Medições Corporais'!$A$4:$A$147,"<"&$C9+1)) | H9: =IF(OR(G9="",G8=""),"",G9-G8) | I9: =IF($D9=0,"",AVERAGEIFS('Medições Corporais'!$D$4:$D$147,'Medições Corporais'!$A$4:$A$147,">="&$B9,'Medições Corporais'!$A$4:$A$147,"<"&$C9+1)) | J9: =IF(OR(I9="",I8=""),"",I9-I8) | K9: =IF($D9=0,"",AVERAGEIFS('Medições Corporais'!$G$4:$G$147,'Medições Corporais'!$A$4:$A$147,">="&$B9,'Medições Corporais'!$A$4:$A$147,"<"&$C9+1)) | L9: =IF($D9=0,"",AVERAGEIFS('Medições Corporais'!$I$4:$I$147,'Medições Corporais'!$A$4:$A$147,">="&$B9,'Medições Corporais'!$A$4:$A$147,"<"&$C9+1)) | M9: =IF($D9=0,"",AVERAGEIFS('Medições Corporais'!$E$4:$E$147,'Medições Corporais'!$A$4:$A$147,">="&$B9,'Medições Corporais'!$A$4:$A$147,"<"&$C9+1)) | N9: =IF($D9=0,"",AVERAGEIFS('Medições Corporais'!$H$4:$H$147,'Medições Corporais'!$A$4:$A$147,">="&$B9,'Medições Corporais'!$A$4:$A$147,"<"&$C9+1)) | O9: =IF($D9=0,"",AVERAGEIFS('Medições Corporais'!$F$4:$F$147,'Medições Corporais'!$A$4:$A$147,">="&$B9,'Medições Corporais'!$A$4:$A$147,"<"&$C9+1)) | P9: =IF($D9=0,"",AVERAGEIFS('Medições Corporais'!$C$4:$C$147,'Medições Corporais'!$A$4:$A$147,">="&$B9,'Medições Corporais'!$A$4:$A$147,"<"&$C9+1)) | Q9: =IF($D9=0,"",AVERAGEIFS('Medições Corporais'!$J$4:$J$147,'Medições Corporais'!$A$4:$A$147,">="&$B9,'Medições Corporais'!$A$4:$A$147,"<"&$C9+1)) | R9: =IF($D9=0,"",AVERAGEIFS('Medições Corporais'!$L$4:$L$147,'Medições Corporais'!$A$4:$A$147,">="&$B9,'Medições Corporais'!$A$4:$A$147,"<"&$C9+1)) | S9: =IF($D9=0,"",AVERAGEIFS('Medições Corporais'!$M$4:$M$147,'Medições Corporais'!$A$4:$A$147,">="&$B9,'Medições Corporais'!$A$4:$A$147,"<"&$C9+1)) | T9: =IFERROR(AVERAGEIFS('Medidas Manuais'!$C$4:$C$25,'Medidas Manuais'!$B$4:$B$25,">="&$B9,'Medidas Manuais'!$B$4:$B$25,"<"&$C9+1),"") | U9: =IFERROR(AVERAGEIFS('Medidas Manuais'!$E$4:$E$25,'Medidas Manuais'!$B$4:$B$25,">="&$B9,'Medidas Manuais'!$B$4:$B$25,"<"&$C9+1),"")
B11: Médias aritméticas das leituras aceites do período (não médias diárias). Variação = média do período menos a do período anterior; gordura em pontos percentuais. 'Período parcial' = começa antes do início da transformação ou termina depois da última leitura. Cintura e pescoço: média das medições manuais com data nesse mês.

Sheet Resumo Semanal
B1: Resumo semanal (domingo a sábado)
B2: Atualizado em 11/10/2026 16:40
A3: Semana | B3: Início | C3: Fim | D3: Leituras | E3: Dias com medição | F3: Período parcial | G3: Peso médio (kg) | H3: Variação do peso (kg) | I3: Gordura média (%) | J3: Variação da gordura (pp) | K3: Músculo médio (kg) | L3: Massa gorda média (kg) | M3: Água média (%) | N3: Proteína média (%) | O3: Massa óssea média (kg) | P3: IMC médio | Q3: Gordura visceral média (índice) | R3: Idade corporal média (anos) | S3: Pontuação corporal média | T3: Cintura (cm) | U3: Variação da cintura (cm) | V3: Pescoço (cm)
A4: 04/01/2026 - 10/01/2026 | B4: 46026 | C4: 46032 | D4: =COUNTIFS('Medições Corporais'!$A$4:$A$147,">="&$B4,'Medições Corporais'!$A$4:$A$147,"<"&$C4+1) | E4: =SUMPRODUCT(('Medições Corporais'!$Q$4:$Q$147>=$B4)*('Medições Corporais'!$Q$4:$Q$147<=$C4)/COUNTIF('Medições Corporais'!$Q$4:$Q$147,'Medições Corporais'!$Q$4:$Q$147)) | F4: =IF($D4=0,"",IF(OR($B4<DATE(2026,1,4),$C4>MAX('Medições Corporais'!$Q$4:$Q$147)),"Sim","Não")) | G4: =IF($D4=0,"",AVERAGEIFS('Medições Corporais'!$B$4:$B$147,'Medições Corporais'!$A$4:$A$147,">="&$B4,'Medições Corporais'!$A$4:$A$147,"<"&$C4+1)) | H4: ="" | I4: =IF($D4=0,"",AVERAGEIFS('Medições Corporais'!$D$4:$D$147,'Medições Corporais'!$A$4:$A$147,">="&$B4,'Medições Corporais'!$A$4:$A$147,"<"&$C4+1)) | J4: ="" | K4: =IF($D4=0,"",AVERAGEIFS('Medições Corporais'!$G$4:$G$147,'Medições Corporais'!$A$4:$A$147,">="&$B4,'Medições Corporais'!$A$4:$A$147,"<"&$C4+1)) | L4: =IF($D4=0,"",AVERAGEIFS('Medições Corporais'!$I$4:$I$147,'Medições Corporais'!$A$4:$A$147,">="&$B4,'Medições Corporais'!$A$4:$A$147,"<"&$C4+1)) | M4: =IF($D4=0,"",AVERAGEIFS('Medições Corporais'!$E$4:$E$147,'Medições Corporais'!$A$4:$A$147,">="&$B4,'Medições Corporais'!$A$4:$A$147,"<"&$C4+1)) | N4: =IF($D4=0,"",AVERAGEIFS('Medições Corporais'!$H$4:$H$147,'Medições Corporais'!$A$4:$A$147,">="&$B4,'Medições Corporais'!$A$4:$A$147,"<"&$C4+1)) | O4: =IF($D4=0,"",AVERAGEIFS('Medições Corporais'!$F$4:$F$147,'Medições Corporais'!$A$4:$A$147,">="&$B4,'Medições Corporais'!$A$4:$A$147,"<"&$C4+1)) | P4: =IF($D4=0,"",AVERAGEIFS('Medições Corporais'!$C$4:$C$147,'Medições Corporais'!$A$4:$A$147,">="&$B4,'Medições Corporais'!$A$4:$A$147,"<"&$C4+1)) | Q4: =IF($D4=0,"",AVERAGEIFS('Medições Corporais'!$J$4:$J$147,'Medições Corporais'!$A$4:$A$147,">="&$B4,'Medições Corporais'!$A$4:$A$147,"<"&$C4+1)) | R4: =IF($D4=0,"",AVERAGEIFS('Medições Corporais'!$L$4:$L$147,'Medições Corporais'!$A$4:$A$147,">="&$B4,'Medições Corporais'!$A$4:$A$147,"<"&$C4+1)) | S4: =IF($D4=0,"",AVERAGEIFS('Medições Corporais'!$M$4:$M$147,'Medições Corporais'!$A$4:$A$147,">="&$B4,'Medições Corporais'!$A$4:$A$147,"<"&$C4+1)) | T4: =IFERROR(IF(INDEX('Medidas Manuais'!$C$4:$C$25,MATCH($A4,'Medidas Manuais'!$A$4:$A$25,0))="","",INDEX('Medidas Manuais'!$C$4:$C$25,MATCH($A4,'Medidas Manuais'!$A$4:$A$25,0))),"") | U4: =IFERROR(IF(INDEX('Medidas Manuais'!$D$4:$D$25,MATCH($A4,'Medidas Manuais'!$A$4:$A$25,0))="","",INDEX('Medidas Manuais'!$D$4:$D$25,MATCH($A4,'Medidas Manuais'!$A$4:$A$25,0))),"") | V4: =IFERROR(IF(INDEX('Medidas Manuais'!$E$4:$E$25,MATCH($A4,'Medidas Manuais'!$A$4:$A$25,0))="","",INDEX('Medidas Manuais'!$E$4:$E$25,MATCH($A4,'Medidas Manuais'!$A$4:$A$25,0))),"")
A5: 11/01/2026 - 17/01/2026 | B5: 46033 | C5: 46039 | D5: =COUNTIFS('Medições Corporais'!$A$4:$A$147,">="&$B5,'Medições Corporais'!$A$4:$A$147,"<"&$C5+1) | E5: =SUMPRODUCT(('Medições Corporais'!$Q$4:$Q$147>=$B5)*('Medições Corporais'!$Q$4:$Q$147<=$C5)/COUNTIF('Medições Corporais'!$Q$4:$Q$147,'Medições Corporais'!$Q$4:$Q$147)) | F5: =IF($D5=0,"",IF(OR($B5<DATE(2026,1,4),$C5>MAX('Medições Corporais'!$Q$4:$Q$147)),"Sim","Não")) | G5: =IF($D5=0,"",AVERAGEIFS('Medições Corporais'!$B$4:$B$147,'Medições Corporais'!$A$4:$A$147,">="&$B5,'Medições Corporais'!$A$4:$A$147,"<"&$C5+1)) | H5: =IF(OR(G5="",G4=""),"",G5-G4) | I5: =IF($D5=0,"",AVERAGEIFS('Medições Corporais'!$D$4:$D$147,'Medições Corporais'!$A$4:$A$147,">="&$B5,'Medições Corporais'!$A$4:$A$147,"<"&$C5+1)) | J5: =IF(OR(I5="",I4=""),"",I5-I4) | K5: =IF($D5=0,"",AVERAGEIFS('Medições Corporais'!$G$4:$G$147,'Medições Corporais'!$A$4:$A$147,">="&$B5,'Medições Corporais'!$A$4:$A$147,"<"&$C5+1)) | L5: =IF($D5=0,"",AVERAGEIFS('Medições Corporais'!$I$4:$I$147,'Medições Corporais'!$A$4:$A$147,">="&$B5,'Medições Corporais'!$A$4:$A$147,"<"&$C5+1)) | M5: =IF($D5=0,"",AVERAGEIFS('Medições Corporais'!$E$4:$E$147,'Medições Corporais'!$A$4:$A$147,">="&$B5,'Medições Corporais'!$A$4:$A$147,"<"&$C5+1)) | N5: =IF($D5=0,"",AVERAGEIFS('Medições Corporais'!$H$4:$H$147,'Medições Corporais'!$A$4:$A$147,">="&$B5,'Medições Corporais'!$A$4:$A$147,"<"&$C5+1)) | O5: =IF($D5=0,"",AVERAGEIFS('Medições Corporais'!$F$4:$F$147,'Medições Corporais'!$A$4:$A$147,">="&$B5,'Medições Corporais'!$A$4:$A$147,"<"&$C5+1)) | P5: =IF($D5=0,"",AVERAGEIFS('Medições Corporais'!$C$4:$C$147,'Medições Corporais'!$A$4:$A$147,">="&$B5,'Medições Corporais'!$A$4:$A$147,"<"&$C5+1)) | Q5: =IF($D5=0,"",AVERAGEIFS('Medições Corporais'!$J$4:$J$147,'Medições Corporais'!$A$4:$A$147,">="&$B5,'Medições Corporais'!$A$4:$A$147,"<"&$C5+1)) | R5: =IF($D5=0,"",AVERAGEIFS('Medições Corporais'!$L$4:$L$147,'Medições Corporais'!$A$4:$A$147,">="&$B5,'Medições Corporais'!$A$4:$A$147,"<"&$C5+1)) | S5: =IF($D5=0,"",AVERAGEIFS('Medições Corporais'!$M$4:$M$147,'Medições Corporais'!$A$4:$A$147,">="&$B5,'Medições Corporais'!$A$4:$A$147,"<"&$C5+1)) | T5: =IFERROR(IF(INDEX('Medidas Manuais'!$C$4:$C$25,MATCH($A5,'Medidas Manuais'!$A$4:$A$25,0))="","",INDEX('Medidas Manuais'!$C$4:$C$25,MATCH($A5,'Medidas Manuais'!$A$4:$A$25,0))),"") | U5: =IFERROR(IF(INDEX('Medidas Manuais'!$D$4:$D$25,MATCH($A5,'Medidas Manuais'!$A$4:$A$25,0))="","",INDEX('Medidas Manuais'!$D$4:$D$25,MATCH($A5,'Medidas Manuais'!$A$4:$A$25,0))),"") | V5: =IFERROR(IF(INDEX('Medidas Manuais'!$E$4:$E$25,MATCH($A5,'Medidas Manuais'!$A$4:$A$25,0))="","",INDEX('Medidas Manuais'!$E$4:$E$25,MATCH($A5,'Medidas Manuais'!$A$4:$A$25,0))),"")
A6: 18/01/2026 - 24/01/2026 | B6: 46040 | C6: 46046 | D6: =COUNTIFS('Medições Corporais'!$A$4:$A$147,">="&$B6,'Medições Corporais'!$A$4:$A$147,"<"&$C6+1) | E6: =SUMPRODUCT(('Medições Corporais'!$Q$4:$Q$147>=$B6)*('Medições Corporais'!$Q$4:$Q$147<=$C6)/COUNTIF('Medições Corporais'!$Q$4:$Q$147,'Medições Corporais'!$Q$4:$Q$147)) | F6: =IF($D6=0,"",IF(OR($B6<DATE(2026,1,4),$C6>MAX('Medições Corporais'!$Q$4:$Q$147)),"Sim","Não")) | G6: =IF($D6=0,"",AVERAGEIFS('Medições Corporais'!$B$4:$B$147,'Medições Corporais'!$A$4:$A$147,">="&$B6,'Medições Corporais'!$A$4:$A$147,"<"&$C6+1)) | H6: =IF(OR(G6="",G5=""),"",G6-G5) | I6: =IF($D6=0,"",AVERAGEIFS('Medições Corporais'!$D$4:$D$147,'Medições Corporais'!$A$4:$A$147,">="&$B6,'Medições Corporais'!$A$4:$A$147,"<"&$C6+1)) | J6: =IF(OR(I6="",I5=""),"",I6-I5) | K6: =IF($D6=0,"",AVERAGEIFS('Medições Corporais'!$G$4:$G$147,'Medições Corporais'!$A$4:$A$147,">="&$B6,'Medições Corporais'!$A$4:$A$147,"<"&$C6+1)) | L6: =IF($D6=0,"",AVERAGEIFS('Medições Corporais'!$I$4:$I$147,'Medições Corporais'!$A$4:$A$147,">="&$B6,'Medições Corporais'!$A$4:$A$147,"<"&$C6+1)) | M6: =IF($D6=0,"",AVERAGEIFS('Medições Corporais'!$E$4:$E$147,'Medições Corporais'!$A$4:$A$147,">="&$B6,'Medições Corporais'!$A$4:$A$147,"<"&$C6+1)) | N6: =IF($D6=0,"",AVERAGEIFS('Medições Corporais'!$H$4:$H$147,'Medições Corporais'!$A$4:$A$147,">="&$B6,'Medições Corporais'!$A$4:$A$147,"<"&$C6+1)) | O6: =IF($D6=0,"",AVERAGEIFS('Medições Corporais'!$F$4:$F$147,'Medições Corporais'!$A$4:$A$147,">="&$B6,'Medições Corporais'!$A$4:$A$147,"<"&$C6+1)) | P6: =IF($D6=0,"",AVERAGEIFS('Medições Corporais'!$C$4:$C$147,'Medições Corporais'!$A$4:$A$147,">="&$B6,'Medições Corporais'!$A$4:$A$147,"<"&$C6+1)) | Q6: =IF($D6=0,"",AVERAGEIFS('Medições Corporais'!$J$4:$J$147,'Medições Corporais'!$A$4:$A$147,">="&$B6,'Medições Corporais'!$A$4:$A$147,"<"&$C6+1)) | R6: =IF($D6=0,"",AVERAGEIFS('Medições Corporais'!$L$4:$L$147,'Medições Corporais'!$A$4:$A$147,">="&$B6,'Medições Corporais'!$A$4:$A$147,"<"&$C6+1)) | S6: =IF($D6=0,"",AVERAGEIFS('Medições Corporais'!$M$4:$M$147,'Medições Corporais'!$A$4:$A$147,">="&$B6,'Medições Corporais'!$A$4:$A$147,"<"&$C6+1)) | T6: =IFERROR(IF(INDEX('Medidas Manuais'!$C$4:$C$25,MATCH($A6,'Medidas Manuais'!$A$4:$A$25,0))="","",INDEX('Medidas Manuais'!$C$4:$C$25,MATCH($A6,'Medidas Manuais'!$A$4:$A$25,0))),"") | U6: =IFERROR(IF(INDEX('Medidas Manuais'!$D$4:$D$25,MATCH($A6,'Medidas Manuais'!$A$4:$A$25,0))="","",INDEX('Medidas Manuais'!$D$4:$D$25,MATCH($A6,'Medidas Manuais'!$A$4:$A$25,0))),"") | V6: =IFERROR(IF(INDEX('Medidas Manuais'!$E$4:$E$25,MATCH($A6,'Medidas Manuais'!$A$4:$A$25,0))="","",INDEX('Medidas Manuais'!$E$4:$E$25,MATCH($A6,'Medidas Manuais'!$A$4:$A$25,0))),"")
A7: 25/01/2026 - 31/01/2026 | B7: 46047 | C7: 46053 | D7: =COUNTIFS('Medições Corporais'!$A$4:$A$147,">="&$B7,'Medições Corporais'!$A$4:$A$147,"<"&$C7+1) | E7: =SUMPRODUCT(('Medições Corporais'!$Q$4:$Q$147>=$B7)*('Medições Corporais'!$Q$4:$Q$147<=$C7)/COUNTIF('Medições Corporais'!$Q$4:$Q$147,'Medições Corporais'!$Q$4:$Q$147)) | F7: =IF($D7=0,"",IF(OR($B7<DATE(2026,1,4),$C7>MAX('Medições Corporais'!$Q$4:$Q$147)),"Sim","Não")) | G7: =IF($D7=0,"",AVERAGEIFS('Medições Corporais'!$B$4:$B$147,'Medições Corporais'!$A$4:$A$147,">="&$B7,'Medições Corporais'!$A$4:$A$147,"<"&$C7+1)) | H7: =IF(OR(G7="",G6=""),"",G7-G6) | I7: =IF($D7=0,"",AVERAGEIFS('Medições Corporais'!$D$4:$D$147,'Medições Corporais'!$A$4:$A$147,">="&$B7,'Medições Corporais'!$A$4:$A$147,"<"&$C7+1)) | J7: =IF(OR(I7="",I6=""),"",I7-I6) | K7: =IF($D7=0,"",AVERAGEIFS('Medições Corporais'!$G$4:$G$147,'Medições Corporais'!$A$4:$A$147,">="&$B7,'Medições Corporais'!$A$4:$A$147,"<"&$C7+1)) | L7: =IF($D7=0,"",AVERAGEIFS('Medições Corporais'!$I$4:$I$147,'Medições Corporais'!$A$4:$A$147,">="&$B7,'Medições Corporais'!$A$4:$A$147,"<"&$C7+1)) | M7: =IF($D7=0,"",AVERAGEIFS('Medições Corporais'!$E$4:$E$147,'Medições Corporais'!$A$4:$A$147,">="&$B7,'Medições Corporais'!$A$4:$A$147,"<"&$C7+1)) | N7: =IF($D7=0,"",AVERAGEIFS('Medições Corporais'!$H$4:$H$147,'Medições Corporais'!$A$4:$A$147,">="&$B7,'Medições Corporais'!$A$4:$A$147,"<"&$C7+1)) | O7: =IF($D7=0,"",AVERAGEIFS('Medições Corporais'!$F$4:$F$147,'Medições Corporais'!$A$4:$A$147,">="&$B7,'Medições Corporais'!$A$4:$A$147,"<"&$C7+1)) | P7: =IF($D7=0,"",AVERAGEIFS('Medições Corporais'!$C$4:$C$147,'Medições Corporais'!$A$4:$A$147,">="&$B7,'Medições Corporais'!$A$4:$A$147,"<"&$C7+1)) | Q7: =IF($D7=0,"",AVERAGEIFS('Medições Corporais'!$J$4:$J$147,'Medições Corporais'!$A$4:$A$147,">="&$B7,'Medições Corporais'!$A$4:$A$147,"<"&$C7+1)) | R7: =IF($D7=0,"",AVERAGEIFS('Medições Corporais'!$L$4:$L$147,'Medições Corporais'!$A$4:$A$147,">="&$B7,'Medições Corporais'!$A$4:$A$147,"<"&$C7+1)) | S7: =IF($D7=0,"",AVERAGEIFS('Medições Corporais'!$M$4:$M$147,'Medições Corporais'!$A$4:$A$147,">="&$B7,'Medições Corporais'!$A$4:$A$147,"<"&$C7+1)) | T7: =IFERROR(IF(INDEX('Medidas Manuais'!$C$4:$C$25,MATCH($A7,'Medidas Manuais'!$A$4:$A$25,0))="","",INDEX('Medidas Manuais'!$C$4:$C$25,MATCH($A7,'Medidas Manuais'!$A$4:$A$25,0))),"") | U7: =IFERROR(IF(INDEX('Medidas Manuais'!$D$4:$D$25,MATCH($A7,'Medidas Manuais'!$A$4:$A$25,0))="","",INDEX('Medidas Manuais'!$D$4:$D$25,MATCH($A7,'Medidas Manuais'!$A$4:$A$25,0))),"") | V7: =IFERROR(IF(INDEX('Medidas Manuais'!$E$4:$E$25,MATCH($A7,'Medidas Manuais'!$A$4:$A$25,0))="","",INDEX('Medidas Manuais'!$E$4:$E$25,MATCH($A7,'Medidas Manuais'!$A$4:$A$25,0))),"")
A8: 01/02/2026 - 07/02/2026 | B8: 46054 | C8: 46060 | D8: =COUNTIFS('Medições Corporais'!$A$4:$A$147,">="&$B8,'Medições Corporais'!$A$4:$A$147,"<"&$C8+1) | E8: =SUMPRODUCT(('Medições Corporais'!$Q$4:$Q$147>=$B8)*('Medições Corporais'!$Q$4:$Q$147<=$C8)/COUNTIF('Medições Corporais'!$Q$4:$Q$147,'Medições Corporais'!$Q$4:$Q$147)) | F8: =IF($D8=0,"",IF(OR($B8<DATE(2026,1,4),$C8>MAX('Medições Corporais'!$Q$4:$Q$147)),"Sim","Não")) | G8: =IF($D8=0,"",AVERAGEIFS('Medições Corporais'!$B$4:$B$147,'Medições Corporais'!$A$4:$A$147,">="&$B8,'Medições Corporais'!$A$4:$A$147,"<"&$C8+1)) | H8: =IF(OR(G8="",G7=""),"",G8-G7) | I8: =IF($D8=0,"",AVERAGEIFS('Medições Corporais'!$D$4:$D$147,'Medições Corporais'!$A$4:$A$147,">="&$B8,'Medições Corporais'!$A$4:$A$147,"<"&$C8+1)) | J8: =IF(OR(I8="",I7=""),"",I8-I7) | K8: =IF($D8=0,"",AVERAGEIFS('Medições Corporais'!$G$4:$G$147,'Medições Corporais'!$A$4:$A$147,">="&$B8,'Medições Corporais'!$A$4:$A$147,"<"&$C8+1)) | L8: =IF($D8=0,"",AVERAGEIFS('Medições Corporais'!$I$4:$I$147,'Medições Corporais'!$A$4:$A$147,">="&$B8,'Medições Corporais'!$A$4:$A$147,"<"&$C8+1)) | M8: =IF($D8=0,"",AVERAGEIFS('Medições Corporais'!$E$4:$E$147,'Medições Corporais'!$A$4:$A$147,">="&$B8,'Medições Corporais'!$A$4:$A$147,"<"&$C8+1)) | N8: =IF($D8=0,"",AVERAGEIFS('Medições Corporais'!$H$4:$H$147,'Medições Corporais'!$A$4:$A$147,">="&$B8,'Medições Corporais'!$A$4:$A$147,"<"&$C8+1)) | O8: =IF($D8=0,"",AVERAGEIFS('Medições Corporais'!$F$4:$F$147,'Medições Corporais'!$A$4:$A$147,">="&$B8,'Medições Corporais'!$A$4:$A$147,"<"&$C8+1)) | P8: =IF($D8=0,"",AVERAGEIFS('Medições Corporais'!$C$4:$C$147,'Medições Corporais'!$A$4:$A$147,">="&$B8,'Medições Corporais'!$A$4:$A$147,"<"&$C8+1)) | Q8: =IF($D8=0,"",AVERAGEIFS('Medições Corporais'!$J$4:$J$147,'Medições Corporais'!$A$4:$A$147,">="&$B8,'Medições Corporais'!$A$4:$A$147,"<"&$C8+1)) | R8: =IF($D8=0,"",AVERAGEIFS('Medições Corporais'!$L$4:$L$147,'Medições Corporais'!$A$4:$A$147,">="&$B8,'Medições Corporais'!$A$4:$A$147,"<"&$C8+1)) | S8: =IF($D8=0,"",AVERAGEIFS('Medições Corporais'!$M$4:$M$147,'Medições Corporais'!$A$4:$A$147,">="&$B8,'Medições Corporais'!$A$4:$A$147,"<"&$C8+1)) | T8: =IFERROR(IF(INDEX('Medidas Manuais'!$C$4:$C$25,MATCH($A8,'Medidas Manuais'!$A$4:$A$25,0))="","",INDEX('Medidas Manuais'!$C$4:$C$25,MATCH($A8,'Medidas Manuais'!$A$4:$A$25,0))),"") | U8: =IFERROR(IF(INDEX('Medidas Manuais'!$D$4:$D$25,MATCH($A8,'Medidas Manuais'!$A$4:$A$25,0))="","",INDEX('Medidas Manuais'!$D$4:$D$25,MATCH($A8,'Medidas Manuais'!$A$4:$A$25,0))),"") | V8: =IFERROR(IF(INDEX('Medidas Manuais'!$E$4:$E$25,MATCH($A8,'Medidas Manuais'!$A$4:$A$25,0))="","",INDEX('Medidas Manuais'!$E$4:$E$25,MATCH($A8,'Medidas Manuais'!$A$4:$A$25,0))),"")
A9: 08/02/2026 - 14/02/2026 | B9: 46061 | C9: 46067 | D9: =COUNTIFS('Medições Corporais'!$A$4:$A$147,">="&$B9,'Medições Corporais'!$A$4:$A$147,"<"&$C9+1) | E9: =SUMPRODUCT(('Medições Corporais'!$Q$4:$Q$147>=$B9)*('Medições Corporais'!$Q$4:$Q$147<=$C9)/COUNTIF('Medições Corporais'!$Q$4:$Q$147,'Medições Corporais'!$Q$4:$Q$147)) | F9: =IF($D9=0,"",IF(OR($B9<DATE(2026,1,4),$C9>MAX('Medições Corporais'!$Q$4:$Q$147)),"Sim","Não")) | G9: =IF($D9=0,"",AVERAGEIFS('Medições Corporais'!$B$4:$B$147,'Medições Corporais'!$A$4:$A$147,">="&$B9,'Medições Corporais'!$A$4:$A$147,"<"&$C9+1)) | H9: =IF(OR(G9="",G8=""),"",G9-G8) | I9: =IF($D9=0,"",AVERAGEIFS('Medições Corporais'!$D$4:$D$147,'Medições Corporais'!$A$4:$A$147,">="&$B9,'Medições Corporais'!$A$4:$A$147,"<"&$C9+1)) | J9: =IF(OR(I9="",I8=""),"",I9-I8) | K9: =IF($D9=0,"",AVERAGEIFS('Medições Corporais'!$G$4:$G$147,'Medições Corporais'!$A$4:$A$147,">="&$B9,'Medições Corporais'!$A$4:$A$147,"<"&$C9+1)) | L9: =IF($D9=0,"",AVERAGEIFS('Medições Corporais'!$I$4:$I$147,'Medições Corporais'!$A$4:$A$147,">="&$B9,'Medições Corporais'!$A$4:$A$147,"<"&$C9+1)) | M9: =IF($D9=0,"",AVERAGEIFS('Medições Corporais'!$E$4:$E$147,'Medições Corporais'!$A$4:$A$147,">="&$B9,'Medições Corporais'!$A$4:$A$147,"<"&$C9+1)) | N9: =IF($D9=0,"",AVERAGEIFS('Medições Corporais'!$H$4:$H$147,'Medições Corporais'!$A$4:$A$147,">="&$B9,'Medições Corporais'!$A$4:$A$147,"<"&$C9+1)) | O9: =IF($D9=0,"",AVERAGEIFS('Medições Corporais'!$F$4:$F$147,'Medições Corporais'!$A$4:$A$147,">="&$B9,'Medições Corporais'!$A$4:$A$147,"<"&$C9+1)) | P9: =IF($D9=0,"",AVERAGEIFS('Medições Corporais'!$C$4:$C$147,'Medições Corporais'!$A$4:$A$147,">="&$B9,'Medições Corporais'!$A$4:$A$147,"<"&$C9+1)) | Q9: =IF($D9=0,"",AVERAGEIFS('Medições Corporais'!$J$4:$J$147,'Medições Corporais'!$A$4:$A$147,">="&$B9,'Medições Corporais'!$A$4:$A$147,"<"&$C9+1)) | R9: =IF($D9=0,"",AVERAGEIFS('Medições Corporais'!$L$4:$L$147,'Medições Corporais'!$A$4:$A$147,">="&$B9,'Medições Corporais'!$A$4:$A$147,"<"&$C9+1)) | S9: =IF($D9=0,"",AVERAGEIFS('Medições Corporais'!$M$4:$M$147,'Medições Corporais'!$A$4:$A$147,">="&$B9,'Medições Corporais'!$A$4:$A$147,"<"&$C9+1)) | T9: =IFERROR(IF(INDEX('Medidas Manuais'!$C$4:$C$25,MATCH($A9,'Medidas Manuais'!$A$4:$A$25,0))="","",INDEX('Medidas Manuais'!$C$4:$C$25,MATCH($A9,'Medidas Manuais'!$A$4:$A$25,0))),"") | U9: =IFERROR(IF(INDEX('Medidas Manuais'!$D$4:$D$25,MATCH($A9,'Medidas Manuais'!$A$4:$A$25,0))="","",INDEX('Medidas Manuais'!$D$4:$D$25,MATCH($A9,'Medidas Manuais'!$A$4:$A$25,0))),"") | V9: =IFERROR(IF(INDEX('Medidas Manuais'!$E$4:$E$25,MATCH($A9,'Medidas Manuais'!$A$4:$A$25,0))="","",INDEX('Medidas Manuais'!$E$4:$E$25,MATCH($A9,'Medidas Manuais'!$A$4:$A$25,0))),"")
A10: 15/02/2026 - 21/02/2026 | B10: 46068 | C10: 46074 | D10: =COUNTIFS('Medições Corporais'!$A$4:$A$147,">="&$B10,'Medições Corporais'!$A$4:$A$147,"<"&$C10+1) | E10: =SUMPRODUCT(('Medições Corporais'!$Q$4:$Q$147>=$B10)*('Medições Corporais'!$Q$4:$Q$147<=$C10)/COUNTIF('Medições Corporais'!$Q$4:$Q$147,'Medições Corporais'!$Q$4:$Q$147)) | F10: =IF($D10=0,"",IF(OR($B10<DATE(2026,1,4),$C10>MAX('Medições Corporais'!$Q$4:$Q$147)),"Sim","Não")) | G10: =IF($D10=0,"",AVERAGEIFS('Medições Corporais'!$B$4:$B$147,'Medições Corporais'!$A$4:$A$147,">="&$B10,'Medições Corporais'!$A$4:$A$147,"<"&$C10+1)) | H10: =IF(OR(G10="",G9=""),"",G10-G9) | I10: =IF($D10=0,"",AVERAGEIFS('Medições Corporais'!$D$4:$D$147,'Medições Corporais'!$A$4:$A$147,">="&$B10,'Medições Corporais'!$A$4:$A$147,"<"&$C10+1)) | J10: =IF(OR(I10="",I9=""),"",I10-I9) | K10: =IF($D10=0,"",AVERAGEIFS('Medições Corporais'!$G$4:$G$147,'Medições Corporais'!$A$4:$A$147,">="&$B10,'Medições Corporais'!$A$4:$A$147,"<"&$C10+1)) | L10: =IF($D10=0,"",AVERAGEIFS('Medições Corporais'!$I$4:$I$147,'Medições Corporais'!$A$4:$A$147,">="&$B10,'Medições Corporais'!$A$4:$A$147,"<"&$C10+1)) | M10: =IF($D10=0,"",AVERAGEIFS('Medições Corporais'!$E$4:$E$147,'Medições Corporais'!$A$4:$A$147,">="&$B10,'Medições Corporais'!$A$4:$A$147,"<"&$C10+1)) | N10: =IF($D10=0,"",AVERAGEIFS('Medições Corporais'!$H$4:$H$147,'Medições Corporais'!$A$4:$A$147,">="&$B10,'Medições Corporais'!$A$4:$A$147,"<"&$C10+1)) | O10: =IF($D10=0,"",AVERAGEIFS('Medições Corporais'!$F$4:$F$147,'Medições Corporais'!$A$4:$A$147,">="&$B10,'Medições Corporais'!$A$4:$A$147,"<"&$C10+1)) | P10: =IF($D10=0,"",AVERAGEIFS('Medições Corporais'!$C$4:$C$147,'Medições Corporais'!$A$4:$A$147,">="&$B10,'Medições Corporais'!$A$4:$A$147,"<"&$C10+1)) | Q10: =IF($D10=0,"",AVERAGEIFS('Medições Corporais'!$J$4:$J$147,'Medições Corporais'!$A$4:$A$147,">="&$B10,'Medições Corporais'!$A$4:$A$147,"<"&$C10+1)) | R10: =IF($D10=0,"",AVERAGEIFS('Medições Corporais'!$L$4:$L$147,'Medições Corporais'!$A$4:$A$147,">="&$B10,'Medições Corporais'!$A$4:$A$147,"<"&$C10+1)) | S10: =IF($D10=0,"",AVERAGEIFS('Medições Corporais'!$M$4:$M$147,'Medições Corporais'!$A$4:$A$147,">="&$B10,'Medições Corporais'!$A$4:$A$147,"<"&$C10+1)) | T10: =IFERROR(IF(INDEX('Medidas Manuais'!$C$4:$C$25,MATCH($A10,'Medidas Manuais'!$A$4:$A$25,0))="","",INDEX('Medidas Manuais'!$C$4:$C$25,MATCH($A10,'Medidas Manuais'!$A$4:$A$25,0))),"") | U10: =IFERROR(IF(INDEX('Medidas Manuais'!$D$4:$D$25,MATCH($A10,'Medidas Manuais'!$A$4:$A$25,0))="","",INDEX('Medidas Manuais'!$D$4:$D$25,MATCH($A10,'Medidas Manuais'!$A$4:$A$25,0))),"") | V10: =IFERROR(IF(INDEX('Medidas Manuais'!$E$4:$E$25,MATCH($A10,'Medidas Manuais'!$A$4:$A$25,0))="","",INDEX('Medidas Manuais'!$E$4:$E$25,MATCH($A10,'Medidas Manuais'!$A$4:$A$25,0))),"")
A11: 22/02/2026 - 28/02/2026 | B11: 46075 | C11: 46081 | D11: =COUNTIFS('Medições Corporais'!$A$4:$A$147,">="&$B11,'Medições Corporais'!$A$4:$A$147,"<"&$C11+1) | E11: =SUMPRODUCT(('Medições Corporais'!$Q$4:$Q$147>=$B11)*('Medições Corporais'!$Q$4:$Q$147<=$C11)/COUNTIF('Medições Corporais'!$Q$4:$Q$147,'Medições Corporais'!$Q$4:$Q$147)) | F11: =IF($D11=0,"",IF(OR($B11<DATE(2026,1,4),$C11>MAX('Medições Corporais'!$Q$4:$Q$147)),"Sim","Não")) | G11: =IF($D11=0,"",AVERAGEIFS('Medições Corporais'!$B$4:$B$147,'Medições Corporais'!$A$4:$A$147,">="&$B11,'Medições Corporais'!$A$4:$A$147,"<"&$C11+1)) | H11: =IF(OR(G11="",G10=""),"",G11-G10) | I11: =IF($D11=0,"",AVERAGEIFS('Medições Corporais'!$D$4:$D$147,'Medições Corporais'!$A$4:$A$147,">="&$B11,'Medições Corporais'!$A$4:$A$147,"<"&$C11+1)) | J11: =IF(OR(I11="",I10=""),"",I11-I10) | K11: =IF($D11=0,"",AVERAGEIFS('Medições Corporais'!$G$4:$G$147,'Medições Corporais'!$A$4:$A$147,">="&$B11,'Medições Corporais'!$A$4:$A$147,"<"&$C11+1)) | L11: =IF($D11=0,"",AVERAGEIFS('Medições Corporais'!$I$4:$I$147,'Medições Corporais'!$A$4:$A$147,">="&$B11,'Medições Corporais'!$A$4:$A$147,"<"&$C11+1)) | M11: =IF($D11=0,"",AVERAGEIFS('Medições Corporais'!$E$4:$E$147,'Medições Corporais'!$A$4:$A$147,">="&$B11,'Medições Corporais'!$A$4:$A$147,"<"&$C11+1)) | N11: =IF($D11=0,"",AVERAGEIFS('Medições Corporais'!$H$4:$H$147,'Medições Corporais'!$A$4:$A$147,">="&$B11,'Medições Corporais'!$A$4:$A$147,"<"&$C11+1)) | O11: =IF($D11=0,"",AVERAGEIFS('Medições Corporais'!$F$4:$F$147,'Medições Corporais'!$A$4:$A$147,">="&$B11,'Medições Corporais'!$A$4:$A$147,"<"&$C11+1)) | P11: =IF($D11=0,"",AVERAGEIFS('Medições Corporais'!$C$4:$C$147,'Medições Corporais'!$A$4:$A$147,">="&$B11,'Medições Corporais'!$A$4:$A$147,"<"&$C11+1)) | Q11: =IF($D11=0,"",AVERAGEIFS('Medições Corporais'!$J$4:$J$147,'Medições Corporais'!$A$4:$A$147,">="&$B11,'Medições Corporais'!$A$4:$A$147,"<"&$C11+1)) | R11: =IF($D11=0,"",AVERAGEIFS('Medições Corporais'!$L$4:$L$147,'Medições Corporais'!$A$4:$A$147,">="&$B11,'Medições Corporais'!$A$4:$A$147,"<"&$C11+1)) | S11: =IF($D11=0,"",AVERAGEIFS('Medições Corporais'!$M$4:$M$147,'Medições Corporais'!$A$4:$A$147,">="&$B11,'Medições Corporais'!$A$4:$A$147,"<"&$C11+1)) | T11: =IFERROR(IF(INDEX('Medidas Manuais'!$C$4:$C$25,MATCH($A11,'Medidas Manuais'!$A$4:$A$25,0))="","",INDEX('Medidas Manuais'!$C$4:$C$25,MATCH($A11,'Medidas Manuais'!$A$4:$A$25,0))),"") | U11: =IFERROR(IF(INDEX('Medidas Manuais'!$D$4:$D$25,MATCH($A11,'Medidas Manuais'!$A$4:$A$25,0))="","",INDEX('Medidas Manuais'!$D$4:$D$25,MATCH($A11,'Medidas Manuais'!$A$4:$A$25,0))),"") | V11: =IFERROR(IF(INDEX('Medidas Manuais'!$E$4:$E$25,MATCH($A11,'Medidas Manuais'!$A$4:$A$25,0))="","",INDEX('Medidas Manuais'!$E$4:$E$25,MATCH($A11,'Medidas Manuais'!$A$4:$A$25,0))),"")
A12: 01/03/2026 - 07/03/2026 | B12: 46082 | C12: 46088 | D12: =COUNTIFS('Medições Corporais'!$A$4:$A$147,">="&$B12,'Medições Corporais'!$A$4:$A$147,"<"&$C12+1) | E12: =SUMPRODUCT(('Medições Corporais'!$Q$4:$Q$147>=$B12)*('Medições Corporais'!$Q$4:$Q$147<=$C12)/COUNTIF('Medições Corporais'!$Q$4:$Q$147,'Medições Corporais'!$Q$4:$Q$147)) | F12: =IF($D12=0,"",IF(OR($B12<DATE(2026,1,4),$C12>MAX('Medições Corporais'!$Q$4:$Q$147)),"Sim","Não")) | G12: =IF($D12=0,"",AVERAGEIFS('Medições Corporais'!$B$4:$B$147,'Medições Corporais'!$A$4:$A$147,">="&$B12,'Medições Corporais'!$A$4:$A$147,"<"&$C12+1)) | H12: =IF(OR(G12="",G11=""),"",G12-G11) | I12: =IF($D12=0,"",AVERAGEIFS('Medições Corporais'!$D$4:$D$147,'Medições Corporais'!$A$4:$A$147,">="&$B12,'Medições Corporais'!$A$4:$A$147,"<"&$C12+1)) | J12: =IF(OR(I12="",I11=""),"",I12-I11) | K12: =IF($D12=0,"",AVERAGEIFS('Medições Corporais'!$G$4:$G$147,'Medições Corporais'!$A$4:$A$147,">="&$B12,'Medições Corporais'!$A$4:$A$147,"<"&$C12+1)) | L12: =IF($D12=0,"",AVERAGEIFS('Medições Corporais'!$I$4:$I$147,'Medições Corporais'!$A$4:$A$147,">="&$B12,'Medições Corporais'!$A$4:$A$147,"<"&$C12+1)) | M12: =IF($D12=0,"",AVERAGEIFS('Medições Corporais'!$E$4:$E$147,'Medições Corporais'!$A$4:$A$147,">="&$B12,'Medições Corporais'!$A$4:$A$147,"<"&$C12+1)) | N12: =IF($D12=0,"",AVERAGEIFS('Medições Corporais'!$H$4:$H$147,'Medições Corporais'!$A$4:$A$147,">="&$B12,'Medições Corporais'!$A$4:$A$147,"<"&$C12+1)) | O12: =IF($D12=0,"",AVERAGEIFS('Medições Corporais'!$F$4:$F$147,'Medições Corporais'!$A$4:$A$147,">="&$B12,'Medições Corporais'!$A$4:$A$147,"<"&$C12+1)) | P12: =IF($D12=0,"",AVERAGEIFS('Medições Corporais'!$C$4:$C$147,'Medições Corporais'!$A$4:$A$147,">="&$B12,'Medições Corporais'!$A$4:$A$147,"<"&$C12+1)) | Q12: =IF($D12=0,"",AVERAGEIFS('Medições Corporais'!$J$4:$J$147,'Medições Corporais'!$A$4:$A$147,">="&$B12,'Medições Corporais'!$A$4:$A$147,"<"&$C12+1)) | R12: =IF($D12=0,"",AVERAGEIFS('Medições Corporais'!$L$4:$L$147,'Medições Corporais'!$A$4:$A$147,">="&$B12,'Medições Corporais'!$A$4:$A$147,"<"&$C12+1)) | S12: =IF($D12=0,"",AVERAGEIFS('Medições Corporais'!$M$4:$M$147,'Medições Corporais'!$A$4:$A$147,">="&$B12,'Medições Corporais'!$A$4:$A$147,"<"&$C12+1)) | T12: =IFERROR(IF(INDEX('Medidas Manuais'!$C$4:$C$25,MATCH($A12,'Medidas Manuais'!$A$4:$A$25,0))="","",INDEX('Medidas Manuais'!$C$4:$C$25,MATCH($A12,'Medidas Manuais'!$A$4:$A$25,0))),"") | U12: =IFERROR(IF(INDEX('Medidas Manuais'!$D$4:$D$25,MATCH($A12,'Medidas Manuais'!$A$4:$A$25,0))="","",INDEX('Medidas Manuais'!$D$4:$D$25,MATCH($A12,'Medidas Manuais'!$A$4:$A$25,0))),"") | V12: =IFERROR(IF(INDEX('Medidas Manuais'!$E$4:$E$25,MATCH($A12,'Medidas Manuais'!$A$4:$A$25,0))="","",INDEX('Medidas Manuais'!$E$4:$E$25,MATCH($A12,'Medidas Manuais'!$A$4:$A$25,0))),"")
A13: 08/03/2026 - 14/03/2026 | B13: 46089 | C13: 46095 | D13: =COUNTIFS('Medições Corporais'!$A$4:$A$147,">="&$B13,'Medições Corporais'!$A$4:$A$147,"<"&$C13+1) | E13: =SUMPRODUCT(('Medições Corporais'!$Q$4:$Q$147>=$B13)*('Medições Corporais'!$Q$4:$Q$147<=$C13)/COUNTIF('Medições Corporais'!$Q$4:$Q$147,'Medições Corporais'!$Q$4:$Q$147)) | F13: =IF($D13=0,"",IF(OR($B13<DATE(2026,1,4),$C13>MAX('Medições Corporais'!$Q$4:$Q$147)),"Sim","Não")) | G13: =IF($D13=0,"",AVERAGEIFS('Medições Corporais'!$B$4:$B$147,'Medições Corporais'!$A$4:$A$147,">="&$B13,'Medições Corporais'!$A$4:$A$147,"<"&$C13+1)) | H13: =IF(OR(G13="",G12=""),"",G13-G12) | I13: =IF($D13=0,"",AVERAGEIFS('Medições Corporais'!$D$4:$D$147,'Medições Corporais'!$A$4:$A$147,">="&$B13,'Medições Corporais'!$A$4:$A$147,"<"&$C13+1)) | J13: =IF(OR(I13="",I12=""),"",I13-I12) | K13: =IF($D13=0,"",AVERAGEIFS('Medições Corporais'!$G$4:$G$147,'Medições Corporais'!$A$4:$A$147,">="&$B13,'Medições Corporais'!$A$4:$A$147,"<"&$C13+1)) | L13: =IF($D13=0,"",AVERAGEIFS('Medições Corporais'!$I$4:$I$147,'Medições Corporais'!$A$4:$A$147,">="&$B13,'Medições Corporais'!$A$4:$A$147,"<"&$C13+1)) | M13: =IF($D13=0,"",AVERAGEIFS('Medições Corporais'!$E$4:$E$147,'Medições Corporais'!$A$4:$A$147,">="&$B13,'Medições Corporais'!$A$4:$A$147,"<"&$C13+1)) | N13: =IF($D13=0,"",AVERAGEIFS('Medições Corporais'!$H$4:$H$147,'Medições Corporais'!$A$4:$A$147,">="&$B13,'Medições Corporais'!$A$4:$A$147,"<"&$C13+1)) | O13: =IF($D13=0,"",AVERAGEIFS('Medições Corporais'!$F$4:$F$147,'Medições Corporais'!$A$4:$A$147,">="&$B13,'Medições Corporais'!$A$4:$A$147,"<"&$C13+1)) | P13: =IF($D13=0,"",AVERAGEIFS('Medições Corporais'!$C$4:$C$147,'Medições Corporais'!$A$4:$A$147,">="&$B13,'Medições Corporais'!$A$4:$A$147,"<"&$C13+1)) | Q13: =IF($D13=0,"",AVERAGEIFS('Medições Corporais'!$J$4:$J$147,'Medições Corporais'!$A$4:$A$147,">="&$B13,'Medições Corporais'!$A$4:$A$147,"<"&$C13+1)) | R13: =IF($D13=0,"",AVERAGEIFS('Medições Corporais'!$L$4:$L$147,'Medições Corporais'!$A$4:$A$147,">="&$B13,'Medições Corporais'!$A$4:$A$147,"<"&$C13+1)) | S13: =IF($D13=0,"",AVERAGEIFS('Medições Corporais'!$M$4:$M$147,'Medições Corporais'!$A$4:$A$147,">="&$B13,'Medições Corporais'!$A$4:$A$147,"<"&$C13+1)) | T13: =IFERROR(IF(INDEX('Medidas Manuais'!$C$4:$C$25,MATCH($A13,'Medidas Manuais'!$A$4:$A$25,0))="","",INDEX('Medidas Manuais'!$C$4:$C$25,MATCH($A13,'Medidas Manuais'!$A$4:$A$25,0))),"") | U13: =IFERROR(IF(INDEX('Medidas Manuais'!$D$4:$D$25,MATCH($A13,'Medidas Manuais'!$A$4:$A$25,0))="","",INDEX('Medidas Manuais'!$D$4:$D$25,MATCH($A13,'Medidas Manuais'!$A$4:$A$25,0))),"") | V13: =IFERROR(IF(INDEX('Medidas Manuais'!$E$4:$E$25,MATCH($A13,'Medidas Manuais'!$A$4:$A$25,0))="","",INDEX('Medidas Manuais'!$E$4:$E$25,MATCH($A13,'Medidas Manuais'!$A$4:$A$25,0))),"")
A14: 15/03/2026 - 21/03/2026 | B14: 46096 | C14: 46102 | D14: =COUNTIFS('Medições Corporais'!$A$4:$A$147,">="&$B14,'Medições Corporais'!$A$4:$A$147,"<"&$C14+1) | E14: =SUMPRODUCT(('Medições Corporais'!$Q$4:$Q$147>=$B14)*('Medições Corporais'!$Q$4:$Q$147<=$C14)/COUNTIF('Medições Corporais'!$Q$4:$Q$147,'Medições Corporais'!$Q$4:$Q$147)) | F14: =IF($D14=0,"",IF(OR($B14<DATE(2026,1,4),$C14>MAX('Medições Corporais'!$Q$4:$Q$147)),"Sim","Não")) | G14: =IF($D14=0,"",AVERAGEIFS('Medições Corporais'!$B$4:$B$147,'Medições Corporais'!$A$4:$A$147,">="&$B14,'Medições Corporais'!$A$4:$A$147,"<"&$C14+1)) | H14: =IF(OR(G14="",G13=""),"",G14-G13) | I14: =IF($D14=0,"",AVERAGEIFS('Medições Corporais'!$D$4:$D$147,'Medições Corporais'!$A$4:$A$147,">="&$B14,'Medições Corporais'!$A$4:$A$147,"<"&$C14+1)) | J14: =IF(OR(I14="",I13=""),"",I14-I13) | K14: =IF($D14=0,"",AVERAGEIFS('Medições Corporais'!$G$4:$G$147,'Medições Corporais'!$A$4:$A$147,">="&$B14,'Medições Corporais'!$A$4:$A$147,"<"&$C14+1)) | L14: =IF($D14=0,"",AVERAGEIFS('Medições Corporais'!$I$4:$I$147,'Medições Corporais'!$A$4:$A$147,">="&$B14,'Medições Corporais'!$A$4:$A$147,"<"&$C14+1)) | M14: =IF($D14=0,"",AVERAGEIFS('Medições Corporais'!$E$4:$E$147,'Medições Corporais'!$A$4:$A$147,">="&$B14,'Medições Corporais'!$A$4:$A$147,"<"&$C14+1)) | N14: =IF($D14=0,"",AVERAGEIFS('Medições Corporais'!$H$4:$H$147,'Medições Corporais'!$A$4:$A$147,">="&$B14,'Medições Corporais'!$A$4:$A$147,"<"&$C14+1)) | O14: =IF($D14=0,"",AVERAGEIFS('Medições Corporais'!$F$4:$F$147,'Medições Corporais'!$A$4:$A$147,">="&$B14,'Medições Corporais'!$A$4:$A$147,"<"&$C14+1)) | P14: =IF($D14=0,"",AVERAGEIFS('Medições Corporais'!$C$4:$C$147,'Medições Corporais'!$A$4:$A$147,">="&$B14,'Medições Corporais'!$A$4:$A$147,"<"&$C14+1)) | Q14: =IF($D14=0,"",AVERAGEIFS('Medições Corporais'!$J$4:$J$147,'Medições Corporais'!$A$4:$A$147,">="&$B14,'Medições Corporais'!$A$4:$A$147,"<"&$C14+1)) | R14: =IF($D14=0,"",AVERAGEIFS('Medições Corporais'!$L$4:$L$147,'Medições Corporais'!$A$4:$A$147,">="&$B14,'Medições Corporais'!$A$4:$A$147,"<"&$C14+1)) | S14: =IF($D14=0,"",AVERAGEIFS('Medições Corporais'!$M$4:$M$147,'Medições Corporais'!$A$4:$A$147,">="&$B14,'Medições Corporais'!$A$4:$A$147,"<"&$C14+1)) | T14: =IFERROR(IF(INDEX('Medidas Manuais'!$C$4:$C$25,MATCH($A14,'Medidas Manuais'!$A$4:$A$25,0))="","",INDEX('Medidas Manuais'!$C$4:$C$25,MATCH($A14,'Medidas Manuais'!$A$4:$A$25,0))),"") | U14: =IFERROR(IF(INDEX('Medidas Manuais'!$D$4:$D$25,MATCH($A14,'Medidas Manuais'!$A$4:$A$25,0))="","",INDEX('Medidas Manuais'!$D$4:$D$25,MATCH($A14,'Medidas Manuais'!$A$4:$A$25,0))),"") | V14: =IFERROR(IF(INDEX('Medidas Manuais'!$E$4:$E$25,MATCH($A14,'Medidas Manuais'!$A$4:$A$25,0))="","",INDEX('Medidas Manuais'!$E$4:$E$25,MATCH($A14,'Medidas Manuais'!$A$4:$A$25,0))),"")
A15: 22/03/2026 - 28/03/2026 | B15: 46103 | C15: 46109 | D15: =COUNTIFS('Medições Corporais'!$A$4:$A$147,">="&$B15,'Medições Corporais'!$A$4:$A$147,"<"&$C15+1) | E15: =SUMPRODUCT(('Medições Corporais'!$Q$4:$Q$147>=$B15)*('Medições Corporais'!$Q$4:$Q$147<=$C15)/COUNTIF('Medições Corporais'!$Q$4:$Q$147,'Medições Corporais'!$Q$4:$Q$147)) | F15: =IF($D15=0,"",IF(OR($B15<DATE(2026,1,4),$C15>MAX('Medições Corporais'!$Q$4:$Q$147)),"Sim","Não")) | G15: =IF($D15=0,"",AVERAGEIFS('Medições Corporais'!$B$4:$B$147,'Medições Corporais'!$A$4:$A$147,">="&$B15,'Medições Corporais'!$A$4:$A$147,"<"&$C15+1)) | H15: =IF(OR(G15="",G14=""),"",G15-G14) | I15: =IF($D15=0,"",AVERAGEIFS('Medições Corporais'!$D$4:$D$147,'Medições Corporais'!$A$4:$A$147,">="&$B15,'Medições Corporais'!$A$4:$A$147,"<"&$C15+1)) | J15: =IF(OR(I15="",I14=""),"",I15-I14) | K15: =IF($D15=0,"",AVERAGEIFS('Medições Corporais'!$G$4:$G$147,'Medições Corporais'!$A$4:$A$147,">="&$B15,'Medições Corporais'!$A$4:$A$147,"<"&$C15+1)) | L15: =IF($D15=0,"",AVERAGEIFS('Medições Corporais'!$I$4:$I$147,'Medições Corporais'!$A$4:$A$147,">="&$B15,'Medições Corporais'!$A$4:$A$147,"<"&$C15+1)) | M15: =IF($D15=0,"",AVERAGEIFS('Medições Corporais'!$E$4:$E$147,'Medições Corporais'!$A$4:$A$147,">="&$B15,'Medições Corporais'!$A$4:$A$147,"<"&$C15+1)) | N15: =IF($D15=0,"",AVERAGEIFS('Medições Corporais'!$H$4:$H$147,'Medições Corporais'!$A$4:$A$147,">="&$B15,'Medições Corporais'!$A$4:$A$147,"<"&$C15+1)) | O15: =IF($D15=0,"",AVERAGEIFS('Medições Corporais'!$F$4:$F$147,'Medições Corporais'!$A$4:$A$147,">="&$B15,'Medições Corporais'!$A$4:$A$147,"<"&$C15+1)) | P15: =IF($D15=0,"",AVERAGEIFS('Medições Corporais'!$C$4:$C$147,'Medições Corporais'!$A$4:$A$147,">="&$B15,'Medições Corporais'!$A$4:$A$147,"<"&$C15+1)) | Q15: =IF($D15=0,"",AVERAGEIFS('Medições Corporais'!$J$4:$J$147,'Medições Corporais'!$A$4:$A$147,">="&$B15,'Medições Corporais'!$A$4:$A$147,"<"&$C15+1)) | R15: =IF($D15=0,"",AVERAGEIFS('Medições Corporais'!$L$4:$L$147,'Medições Corporais'!$A$4:$A$147,">="&$B15,'Medições Corporais'!$A$4:$A$147,"<"&$C15+1)) | S15: =IF($D15=0,"",AVERAGEIFS('Medições Corporais'!$M$4:$M$147,'Medições Corporais'!$A$4:$A$147,">="&$B15,'Medições Corporais'!$A$4:$A$147,"<"&$C15+1)) | T15: =IFERROR(IF(INDEX('Medidas Manuais'!$C$4:$C$25,MATCH($A15,'Medidas Manuais'!$A$4:$A$25,0))="","",INDEX('Medidas Manuais'!$C$4:$C$25,MATCH($A15,'Medidas Manuais'!$A$4:$A$25,0))),"") | U15: =IFERROR(IF(INDEX('Medidas Manuais'!$D$4:$D$25,MATCH($A15,'Medidas Manuais'!$A$4:$A$25,0))="","",INDEX('Medidas Manuais'!$D$4:$D$25,MATCH($A15,'Medidas Manuais'!$A$4:$A$25,0))),"") | V15: =IFERROR(IF(INDEX('Medidas Manuais'!$E$4:$E$25,MATCH($A15,'Medidas Manuais'!$A$4:$A$25,0))="","",INDEX('Medidas Manuais'!$E$4:$E$25,MATCH($A15,'Medidas Manuais'!$A$4:$A$25,0))),"")
A16: 29/03/2026 - 04/04/2026 | B16: 46110 | C16: 46116 | D16: =COUNTIFS('Medições Corporais'!$A$4:$A$147,">="&$B16,'Medições Corporais'!$A$4:$A$147,"<"&$C16+1) | E16: =SUMPRODUCT(('Medições Corporais'!$Q$4:$Q$147>=$B16)*('Medições Corporais'!$Q$4:$Q$147<=$C16)/COUNTIF('Medições Corporais'!$Q$4:$Q$147,'Medições Corporais'!$Q$4:$Q$147)) | F16: =IF($D16=0,"",IF(OR($B16<DATE(2026,1,4),$C16>MAX('Medições Corporais'!$Q$4:$Q$147)),"Sim","Não")) | G16: =IF($D16=0,"",AVERAGEIFS('Medições Corporais'!$B$4:$B$147,'Medições Corporais'!$A$4:$A$147,">="&$B16,'Medições Corporais'!$A$4:$A$147,"<"&$C16+1)) | H16: =IF(OR(G16="",G15=""),"",G16-G15) | I16: =IF($D16=0,"",AVERAGEIFS('Medições Corporais'!$D$4:$D$147,'Medições Corporais'!$A$4:$A$147,">="&$B16,'Medições Corporais'!$A$4:$A$147,"<"&$C16+1)) | J16: =IF(OR(I16="",I15=""),"",I16-I15) | K16: =IF($D16=0,"",AVERAGEIFS('Medições Corporais'!$G$4:$G$147,'Medições Corporais'!$A$4:$A$147,">="&$B16,'Medições Corporais'!$A$4:$A$147,"<"&$C16+1)) | L16: =IF($D16=0,"",AVERAGEIFS('Medições Corporais'!$I$4:$I$147,'Medições Corporais'!$A$4:$A$147,">="&$B16,'Medições Corporais'!$A$4:$A$147,"<"&$C16+1)) | M16: =IF($D16=0,"",AVERAGEIFS('Medições Corporais'!$E$4:$E$147,'Medições Corporais'!$A$4:$A$147,">="&$B16,'Medições Corporais'!$A$4:$A$147,"<"&$C16+1)) | N16: =IF($D16=0,"",AVERAGEIFS('Medições Corporais'!$H$4:$H$147,'Medições Corporais'!$A$4:$A$147,">="&$B16,'Medições Corporais'!$A$4:$A$147,"<"&$C16+1)) | O16: =IF($D16=0,"",AVERAGEIFS('Medições Corporais'!$F$4:$F$147,'Medições Corporais'!$A$4:$A$147,">="&$B16,'Medições Corporais'!$A$4:$A$147,"<"&$C16+1)) | P16: =IF($D16=0,"",AVERAGEIFS('Medições Corporais'!$C$4:$C$147,'Medições Corporais'!$A$4:$A$147,">="&$B16,'Medições Corporais'!$A$4:$A$147,"<"&$C16+1)) | Q16: =IF($D16=0,"",AVERAGEIFS('Medições Corporais'!$J$4:$J$147,'Medições Corporais'!$A$4:$A$147,">="&$B16,'Medições Corporais'!$A$4:$A$147,"<"&$C16+1)) | R16: =IF($D16=0,"",AVERAGEIFS('Medições Corporais'!$L$4:$L$147,'Medições Corporais'!$A$4:$A$147,">="&$B16,'Medições Corporais'!$A$4:$A$147,"<"&$C16+1)) | S16: =IF($D16=0,"",AVERAGEIFS('Medições Corporais'!$M$4:$M$147,'Medições Corporais'!$A$4:$A$147,">="&$B16,'Medições Corporais'!$A$4:$A$147,"<"&$C16+1)) | T16: =IFERROR(IF(INDEX('Medidas Manuais'!$C$4:$C$25,MATCH($A16,'Medidas Manuais'!$A$4:$A$25,0))="","",INDEX('Medidas Manuais'!$C$4:$C$25,MATCH($A16,'Medidas Manuais'!$A$4:$A$25,0))),"") | U16: =IFERROR(IF(INDEX('Medidas Manuais'!$D$4:$D$25,MATCH($A16,'Medidas Manuais'!$A$4:$A$25,0))="","",INDEX('Medidas Manuais'!$D$4:$D$25,MATCH($A16,'Medidas Manuais'!$A$4:$A$25,0))),"") | V16: =IFERROR(IF(INDEX('Medidas Manuais'!$E$4:$E$25,MATCH($A16,'Medidas Manuais'!$A$4:$A$25,0))="","",INDEX('Medidas Manuais'!$E$4:$E$25,MATCH($A16,'Medidas Manuais'!$A$4:$A$25,0))),"")
... A25: 31/05/2026 - 06/06/2026 | B25: 46173 | C25: 46179 | D25: =COUNTIFS('Medições Corporais'!$A$4:$A$147,">="&$B25,'Medições Corporais'!$A$4:$A$147,"<"&$C25+1) | E25: =SUMPRODUCT(('Medições Corporais'!$Q$4:$Q$147>=$B25)*('Medições Corporais'!$Q$4:$Q$147<=$C25)/COUNTIF('Medições Corporais'!$Q$4:$Q$147,'Medições Corporais'!$Q$4:$Q$147)) | F25: =IF($D25=0,"",IF(OR($B25<DATE(2026,1,4),$C25>MAX('Medições Corporais'!$Q$4:$Q$147)),"Sim","Não")) | G25: =IF($D25=0,"",AVERAGEIFS('Medições Corporais'!$B$4:$B$147,'Medições Corporais'!$A$4:$A$147,">="&$B25,'Medições Corporais'!$A$4:$A$147,"<"&$C25+1)) | H25: =IF(OR(G25="",G24=""),"",G25-G24) | I25: =IF($D25=0,"",AVERAGEIFS('Medições Corporais'!$D$4:$D$147,'Medições Corporais'!$A$4:$A$147,">="&$B25,'Medições Corporais'!$A$4:$A$147,"<"&$C25+1)) | J25: =IF(OR(I25="",I24=""),"",I25-I24) | K25: =IF($D25=0,"",AVERAGEIFS('Medições Corporais'!$G$4:$G$147,'Medições Corporais'!$A$4:$A$147,">="&$B25,'Medições Corporais'!$A$4:$A$147,"<"&$C25+1)) | L25: =IF($D25=0,"",AVERAGEIFS('Medições Corporais'!$I$4:$I$147,'Medições Corporais'!$A$4:$A$147,">="&$B25,'Medições Corporais'!$A$4:$A$147,"<"&$C25+1)) | M25: =IF($D25=0,"",AVERAGEIFS('Medições Corporais'!$E$4:$E$147,'Medições Corporais'!$A$4:$A$147,">="&$B25,'Medições Corporais'!$A$4:$A$147,"<"&$C25+1)) | N25: =IF($D25=0,"",AVERAGEIFS('Medições Corporais'!$H$4:$H$147,'Medições Corporais'!$A$4:$A$147,">="&$B25,'Medições Corporais'!$A$4:$A$147,"<"&$C25+1)) | O25: =IF($D25=0,"",AVERAGEIFS('Medições Corporais'!$F$4:$F$147,'Medições Corporais'!$A$4:$A$147,">="&$B25,'Medições Corporais'!$A$4:$A$147,"<"&$C25+1)) | P25: =IF($D25=0,"",AVERAGEIFS('Medições Corporais'!$C$4:$C$147,'Medições Corporais'!$A$4:$A$147,">="&$B25,'Medições Corporais'!$A$4:$A$147,"<"&$C25+1)) | Q25: =IF($D25=0,"",AVERAGEIFS('Medições Corporais'!$J$4:$J$147,'Medições Corporais'!$A$4:$A$147,">="&$B25,'Medições Corporais'!$A$4:$A$147,"<"&$C25+1)) | R25: =IF($D25=0,"",AVERAGEIFS('Medições Corporais'!$L$4:$L$147,'Medições Corporais'!$A$4:$A$147,">="&$B25,'Medições Corporais'!$A$4:$A$147,"<"&$C25+1)) | S25: =IF($D25=0,"",AVERAGEIFS('Medições Corporais'!$M$4:$M$147,'Medições Corporais'!$A$4:$A$147,">="&$B25,'Medições Corporais'!$A$4:$A$147,"<"&$C25+1)) | T25: =IFERROR(IF(INDEX('Medidas Manuais'!$C$4:$C$25,MATCH($A25,'Medidas Manuais'!$A$4:$A$25,0))="","",INDEX('Medidas Manuais'!$C$4:$C$25,MATCH($A25,'Medidas Manuais'!$A$4:$A$25,0))),"") | U25: =IFERROR(IF(INDEX('Medidas Manuais'!$D$4:$D$25,MATCH($A25,'Medidas Manuais'!$A$4:$A$25,0))="","",INDEX('Medidas Manuais'!$D$4:$D$25,MATCH($A25,'Medidas Manuais'!$A$4:$A$25,0))),"") | V25: =IFERROR(IF(INDEX('Medidas Manuais'!$E$4:$E$25,MATCH($A25,'Medidas Manuais'!$A$4:$A$25,0))="","",INDEX('Medidas Manuais'!$E$4:$E$25,MATCH($A25,'Medidas Manuais'!$A$4:$A$25,0))),"")
B27: Médias aritméticas das leituras aceites do período (não médias diárias). Variação = média do período menos a do período anterior; gordura em pontos percentuais. 'Período parcial' = começa antes do início da transformação ou termina depois da última leitura. Cintura: diferença face à medição anterior disponível.

